{"trial_id": "001", "hyperparameters": {"space": [{"class_name": "Int", "config": {"name": "units", "default": null, "conditions": [], "min_value": 32, "max_value": 512, "step": 32, "sampling": "linear"}}, {"class_name": "Float", "config": {"name": "dropout", "default": 0.0, "conditions": [], "min_value": 0.0, "max_value": 0.5, "step": 0.1, "sampling": "linear"}}, {"class_name": "Choice", "config": {"name": "learning_rate", "default": 0.01, "conditions": [], "values": [0.01, 0.001, 0.0001], "ordered": true}}], "values": {"units": 480, "dropout": 0.4, "learning_rate": 0.0001}}, "metrics": {"metrics": {}}, "score": null, "best_step": 0, "status": "FAILED", "message": "Traceback (most recent call last):\n  File \"/home/rusconbenito@edu.local/anaconda3/envs/NLP/lib/python3.11/site-packages/keras_tuner/engine/base_tuner.py\", line 266, in _try_run_and_update_trial\n    self._run_and_update_trial(trial, *fit_args, **fit_kwargs)\n  File \"/home/rusconbenito@edu.local/anaconda3/envs/NLP/lib/python3.11/site-packages/keras_tuner/engine/base_tuner.py\", line 231, in _run_and_update_trial\n    results = self.run_trial(trial, *fit_args, **fit_kwargs)\n              ^^^^^^^^^^^^^^^^^^^^^^^^^^^^^^^^^^^^^^^^^^^^^^\n  File \"/home/rusconbenito@edu.local/anaconda3/envs/NLP/lib/python3.11/site-packages/keras_tuner/engine/tuner.py\", line 287, in run_trial\n    obj_value = self._build_and_fit_model(trial, *args, **copied_kwargs)\n                ^^^^^^^^^^^^^^^^^^^^^^^^^^^^^^^^^^^^^^^^^^^^^^^^^^^^^^^^\n  File \"/home/rusconbenito@edu.local/anaconda3/envs/NLP/lib/python3.11/site-packages/keras_tuner/engine/tuner.py\", line 214, in _build_and_fit_model\n    results = self.hypermodel.fit(hp, model, *args, **kwargs)\n              ^^^^^^^^^^^^^^^^^^^^^^^^^^^^^^^^^^^^^^^^^^^^^^^\n  File \"/home/rusconbenito@edu.local/anaconda3/envs/NLP/lib/python3.11/site-packages/keras_tuner/engine/hypermodel.py\", line 144, in fit\n    return model.fit(*args, **kwargs)\n           ^^^^^^^^^^^^^^^^^^^^^^^^^^\n  File \"/home/rusconbenito@edu.local/anaconda3/envs/NLP/lib/python3.11/site-packages/keras/utils/traceback_utils.py\", line 70, in error_handler\n    raise e.with_traceback(filtered_tb) from None\n  File \"/tmp/__autograph_generated_file5al1ozz6.py\", line 18, in tf__train_function\n    raise\nValueError: in user code:\n\n    File \"/home/rusconbenito@edu.local/anaconda3/envs/NLP/lib/python3.11/site-packages/keras/engine/training.py\", line 1284, in train_function  *\n        return step_function(self, iterator)\n    File \"/home/rusconbenito@edu.local/anaconda3/envs/NLP/lib/python3.11/site-packages/keras/engine/training.py\", line 1268, in step_function  **\n        outputs = model.distribute_strategy.run(run_step, args=(data,))\n    File \"/home/rusconbenito@edu.local/anaconda3/envs/NLP/lib/python3.11/site-packages/keras/engine/training.py\", line 1249, in run_step  **\n        outputs = model.train_step(data)\n    File \"/home/rusconbenito@edu.local/anaconda3/envs/NLP/lib/python3.11/site-packages/keras/engine/training.py\", line 1050, in train_step\n        y_pred = self(x, training=True)\n    File \"/home/rusconbenito@edu.local/anaconda3/envs/NLP/lib/python3.11/site-packages/keras/utils/traceback_utils.py\", line 70, in error_handler\n        raise e.with_traceback(filtered_tb) from None\n    File \"/home/rusconbenito@edu.local/anaconda3/envs/NLP/lib/python3.11/site-packages/keras/engine/input_spec.py\", line 298, in assert_input_compatibility\n        raise ValueError(\n\n    ValueError: Input 0 of layer \"sequential\" is incompatible with the layer: expected shape=(None, 784), found shape=(16, 20)\n\n"}